Workbook
Name T_corr_150000_1_0: _1_0!$A$1:$M$458
Name T_corr_150000_1_1: _1_1!$A$1:$M$458
Name T_corr_150000_1_2: '1_2'!$A$1:$M$458
Name T_corr_150000_2_0: _2_0!$A$1:$M$458
Name T_corr_150000_2_1: _2_1!$A$1:$M$458
Name T_corr_150000_3_0: _3_0!$A$1:$M$458
Name T_corr_150000_3_1: _3_1!$A$1:$M$458

Sheet _1_0
A1: Nmb_of_pts | B1: 150000, time_0 | C1: 0.2
A6: <Delta.v_1*Delta.v_1>
A7: t | B7: delta_t | C7: 0 | D7: 0.05 | E7: 0.1 | F7: 0.15 | G7: 0.5 | H7: 1 | I7: 1.5 | J7: 2.5 | K7: 5 | L7: 7.5
A8: r | B8: 0 | C8: 0 | D8: -0.025668379 | E8: -0.045899317 | F8: -0.059671811 | G8: -0.1150316 | H8: -0.16472415 | I8: -0.20842443 | J8: -0.27136976 | K8: -0.30730774 | L8: -0.37082757
A9: r | B9: 0.1 | C9: -0.039182098 | D9: -0.044321939 | E9: -0.054497451 | F9: -0.065160354 | G9: -0.1172069 | H9: -0.16549185 | I9: -0.20896955 | J9: -0.27132349 | K9: -0.30815123 | L9: -0.37103917
A10: r | B10: 0.2 | C10: -0.068170136 | D10: -0.070297695 | E10: -0.07376164 | F10: -0.079462512 | G10: -0.1224581 | H10: -0.16875931 | I10: -0.21027394 | J10: -0.27181915 | K10: -0.30879027 | L10: -0.37103671
A11: r | B11: 0.3 | C11: -0.091526859 | D11: -0.09235366 | E11: -0.095133029 | F11: -0.098275961 | G11: -0.13136442 | H11: -0.17348145 | I11: -0.21189822 | J11: -0.27282532 | K11: -0.3098717 | L11: -0.37044245
A12: r | B12: 0.4 | C12: -0.11366219 | D12: -0.11465832 | E12: -0.1154533 | F12: -0.11741081 | G12: -0.14111431 | H12: -0.17947526 | I12: -0.21608944 | J12: -0.27472265 | K12: -0.31122851 | L12: -0.37074133
A13: r | B13: 0.8 | C13: -0.1858302 | D13: -0.18637024 | E13: -0.18607136 | F13: -0.18619345 | G13: -0.19344521 | H13: -0.21474232 | I13: -0.24026854 | J13: -0.28436044 | K13: -0.32141345 | L13: -0.37670869
A14: r | B14: 1.2 | C14: -0.24074019 | D14: -0.24090101 | E14: -0.24161478 | F14: -0.24188131 | G14: -0.24715659 | H14: -0.25657985 | I14: -0.27092891 | J14: -0.30118743 | K14: -0.33620088 | L14: -0.38437425
A15: r | B15: 1.6 | C15: -0.28785868 | D15: -0.28833707 | E15: -0.28851619 | F15: -0.28850631 | G15: -0.29076278 | H15: -0.29708866 | I15: -0.30586803 | J15: -0.31994343 | K15: -0.35094266 | L15: -0.39226811
A18: <Delta.v_1*Delta.v_2>
A19: t | B19: delta_t | C19: 0 | D19: 0.05 | E19: 0.1 | F19: 0.15 | G19: 0.5 | H19: 1 | I19: 1.5 | J19: 2.5 | K19: 5 | L19: 7.5
A20: r | B20: 0 | C20: 0 | D20: -6.1354553e-05 | E20: 0.00012990155 | F20: -0.00047286196 | G20: -0.00021904722 | H20: 0.0004678315 | I20: 0.0011665814 | J20: 0.00033029071 | K20: 0.0021889059 | L20: 0.0020988594
A21: r | B21: 0.1 | C21: 0.00034619322 | D21: 0.00025494709 | E21: -1.4358225e-05 | F21: 7.5502174e-05 | G21: 3.2757325e-05 | H21: 3.2570559e-05 | I21: 0.0011643446 | J21: 0.00039281621 | K21: 0.0015724162 | L21: 0.0021021066
A22: r | B22: 0.2 | C22: -0.00014519839 | D22: 0.00030455013 | E22: -1.9704501e-05 | F22: -0.00049985706 | G22: 0.00015828633 | H22: 0.00052058309 | I22: 0.0010604018 | J22: 1.6756974e-05 | K22: 0.0016173884 | L22: 0.00039166456
A23: r | B23: 0.3 | C23: 0.0011330495 | D23: 0.00094761118 | E23: 0.00069041319 | F23: 0.00040937861 | G23: 0.00071883945 | H23: 0.0010672454 | I23: 0.00089923347 | J23: 0.00060752072 | K23: 0.00061395593 | L23: -0.00068347584
A24: r | B24: 0.4 | C24: 0.0013215977 | D24: 0.0011320315 | E24: 0.0016083889 | F24: 0.00137522 | G24: 0.0011027269 | H24: 0.00063084145 | I24: -0.00067529479 | J24: 0.001147721 | K24: 0.00029878216 | L24: -0.00069835902
A25: r | B25: 0.8 | C25: 0.0027839708 | D25: 0.0021697297 | E25: 0.0023781527 | F25: 0.0026274113 | G25: 0.0018033493 | H25: 0.0011874293 | I25: 0.0014031654 | J25: -6.3308377e-05 | K25: -0.0037623013 | L25: -0.0045955917
A26: r | B26: 1.2 | C26: 0.0010152466 | D26: 0.00089152194 | E26: 0.00034208424 | F26: 0.00052796632 | G26: 0.0018623912 | H26: 0.0016394908 | I26: 0.0016283773 | J26: -0.0019547334 | K26: -0.0073659545 | L26: -0.0080572339
A27: r | B27: 1.6 | C27: 0.0010816048 | D27: 0.0013026456 | E27: 0.00058643543 | F27: 0.0012742972 | G27: 0.0019408432 | H27: 0.0019366812 | I27: -0.0001668921 | J27: -0.0030728117 | K27: -0.010581001 | L27: -0.0087111169
A30: <Delta.v_1*Delta.v_3>
A31: t | B31: delta_t | C31: 0 | D31: 0.05 | E31: 0.1 | F31: 0.15 | G31: 0.5 | H31: 1 | I31: 1.5 | J31: 2.5 | K31: 5 | L31: 7.5
A32: r | B32: 0 | C32: 0 | D32: 0.00030086536 | E32: 0.00051266602 | F32: 0.001163771 | G32: 0.0065315752 | H32: 0.01411043 | I32: 0.017462459 | J32: 0.012492824 | K32: 0.016001286 | L32: 0.017473001
A33: r | B33: 0.1 | C33: 0.00070570085 | D33: 0.00055301131 | E33: 0.00083653665 | F33: 0.0015969261 | G33: 0.0064303778 | H33: 0.015060144 | I33: 0.017888658 | J33: 0.013034068 | K33: 0.016338314 | L33: 0.017645974
A34: r | B34: 0.2 | C34: -0.00051865162 | D34: 0.0002718834 | E34: 0.00027673277 | F34: 0.001389881 | G34: 0.0071265356 | H34: 0.014500304 | I34: 0.018402286 | J34: 0.012740434 | K34: 0.016604761 | L34: 0.017328706
A35: r | B35: 0.3 | C35: -0.00070948292 | D35: -0.0002343773 | E35: 0.00077244085 | F35: 0.001347169 | G35: 0.0074232449 | H35: 0.015366892 | I35: 0.018060646 | J35: 0.012486815 | K35: 0.017110696 | L35: 0.01640974
A36: r | B36: 0.4 | C36: -0.00041138091 | D36: -0.00027831309 | E36: 0.00035882705 | F36: 0.00079309411 | G36: 0.0075857024 | H36: 0.014925372 | I36: 0.017440915 | J36: 0.012711892 | K36: 0.017345625 | L36: 0.016361885
A37: r | B37: 0.8 | C37: 0.00082444363 | D37: 0.0017598963 | E37: 0.0025995316 | F37: 0.003178427 | G37: 0.0080861476 | H37: 0.012948619 | I37: 0.015859243 | J37: 0.013285799 | K37: 0.018163972 | L37: 0.014006247
A38: r | B38: 1.2 | C38: 0.0025215688 | D38: 0.0029649952 | E38: 0.0028874874 | F38: 0.0038442116 | G38: 0.0072046029 | H38: 0.010021579 | I38: 0.012560348 | J38: 0.012070643 | K38: 0.015994444 | L38: 0.013297878
A39: r | B39: 1.6 | C39: 0.0026484998 | D39: 0.0031546339 | E39: 0.003103132 | F39: 0.0040873207 | G39: 0.0048719066 | H39: 0.0088167012 | I39: 0.0097964784 | J39: 0.010188499 | K39: 0.013688426 | L39: 0.0090738946
A42: <Delta.v_2*Delta.v_1>
A43: t | B43: delta_t | C43: 0 | D43: 0.05 | E43: 0.1 | F43: 0.15 | G43: 0.5 | H43: 1 | I43: 1.5 | J43: 2.5 | K43: 5 | L43: 7.5
A44: r | B44: 0 | C44: 0 | D44: -0.00075069335 | E44: -0.00017588472 | F44: -7.732575e-05 | G44: 0.00033237275 | H44: -0.00058716889 | I44: -0.00078340026 | J44: -0.0013070433 | K44: 0.0033487119 | L44: 0.0013530265
A45: r | B45: 0.1 | C45: -0.00058197923 | D45: -0.00010553648 | E45: -0.00038920798 | F45: 0.00013594995 | G45: 0.00071783132 | H45: -0.00040085594 | I45: -8.0852757e-05 | J45: -0.0012111059 | K45: 0.0019317093 | L45: 0.0004899118
A46: r | B46: 0.2 | C46: -0.00069480563 | D46: -0.00055803767 | E46: -0.00027844929 | F46: -6.9126506e-05 | G46: 0.00088181941 | H46: -0.00045697095 | I46: 0.00031994211 | J46: -0.0013821782 | K46: 0.0017149083 | L46: -0.0013544497
A47: r | B47: 0.3 | C47: -0.00086130285 | D47: -0.00025544907 | E47: -0.00041626973 | F47: -0.00054103652 | G47: 0.00074105362 | H47: -0.00015807151 | I47: 0.00010327351 | J47: -0.00086351277 | K47: 0.0012902299 | L47: -0.0029116179
A48: r | B48: 0.4 | C48: -0.0004112537 | D48: 0.0006927052 | E48: 0.00028387965 | F48: 0.00060704606 | G48: 0.00085662108 | H48: -0.00022991492 | I48: 0.000524043 | J48: -0.0006582315 | K48: -2.1969641e-05 | L48: -0.0039053006
A49: r | B49: 0.8 | C49: 0.00030714548 | D49: 0.00032503693 | E49: 0.00017494793 | F49: -0.00010884058 | G49: 0.00025113431 | H49: 0.00020010786 | I49: -0.00038585235 | J49: -0.0013379607 | K49: -0.0025486246 | L49: -0.0077242927
A50: r | B50: 1.2 | C50: 0.00045459148 | D50: 0.00057435303 | E50: 0.00073680005 | F50: 0.00093975595 | G50: 6.4084926e-05 | H50: -0.00021298861 | I50: -0.00046569871 | J50: -0.0010882297 | K50: -0.0057497244 | L50: -0.0093716059
...

Sheet _2_0
A1: Nmb_of_pts | B1: 150000, time_0 | C1: 0.2
A6: <Delta.v_1*Delta.v_1>
A7: t | B7: delta_t | C7: 0 | D7: 0.05 | E7: 0.1 | F7: 0.15 | G7: 0.5 | H7: 1 | I7: 1.5 | J7: 2.5 | K7: 5 | L7: 7.5
A8: r | B8: 0 | C8: 0 | D8: -0.026099918 | E8: -0.045663673 | F8: -0.059779468 | G8: -0.11474532 | H8: -0.16422832 | I8: -0.20780059 | J8: -0.26995403 | K8: -0.30840349 | L8: -0.37124132
A9: r | B9: 0.1 | C9: -0.039687078 | D9: -0.044490652 | E9: -0.054943655 | F9: -0.06528633 | G9: -0.11610467 | H9: -0.16591944 | I9: -0.20889214 | J9: -0.27046161 | K9: -0.30886081 | L9: -0.37034108
A10: r | B10: 0.2 | C10: -0.069480957 | D10: -0.071890258 | E10: -0.075217757 | F10: -0.08087312 | G10: -0.12156785 | H10: -0.16952519 | I10: -0.21049483 | J10: -0.27130578 | K10: -0.30890195 | L10: -0.37098352
A11: r | B11: 0.3 | C11: -0.093761508 | D11: -0.094452687 | E11: -0.096050421 | F11: -0.098601552 | G11: -0.13125825 | H11: -0.17417221 | I11: -0.21330669 | J11: -0.27165558 | K11: -0.31045163 | L11: -0.371461
A12: r | B12: 0.4 | C12: -0.11495038 | D12: -0.11553877 | E12: -0.11545061 | F12: -0.11751918 | G12: -0.14172839 | H12: -0.18026417 | I12: -0.21678081 | J12: -0.27408002 | K12: -0.31099893 | L12: -0.37236308
A13: r | B13: 0.8 | C13: -0.18679628 | D13: -0.18656033 | E13: -0.18675651 | F13: -0.18711176 | G13: -0.19435876 | H13: -0.21544954 | I13: -0.24179063 | J13: -0.28389236 | K13: -0.32183602 | L13: -0.37698456
A14: r | B14: 1.2 | C14: -0.24107609 | D14: -0.24195484 | E14: -0.24179414 | F14: -0.24228042 | G14: -0.24555791 | H14: -0.25707167 | I14: -0.27218381 | J14: -0.3012705 | K14: -0.33564845 | L14: -0.38450236
A15: r | B15: 1.6 | C15: -0.28832491 | D15: -0.28850628 | E15: -0.28792629 | F15: -0.28866432 | G15: -0.29079976 | H15: -0.29588656 | I15: -0.30503746 | J15: -0.32155313 | K15: -0.35259789 | L15: -0.39302215
A18: <Delta.v_1*Delta.v_2>
A19: t | B19: delta_t | C19: 0 | D19: 0.05 | E19: 0.1 | F19: 0.15 | G19: 0.5 | H19: 1 | I19: 1.5 | J19: 2.5 | K19: 5 | L19: 7.5
A20: r | B20: 0 | C20: 0 | D20: 0.00018522594 | E20: 0.00096072225 | F20: 0.00067303142 | G20: -0.0002016739 | H20: 0.00033246244 | I20: -0.00013794956 | J20: 0.00081292489 | K20: 0.0018639125 | L20: 0.0018396056
A21: r | B21: 0.1 | C21: 0.00022087762 | D21: 0.00026991736 | E21: 0.00038707252 | F21: 0.00060205225 | G21: -0.00048274802 | H21: -0.00024871087 | I21: -0.00048824705 | J21: 0.00043804109 | K21: 0.00087570344 | L21: 8.8108284e-05
A22: r | B22: 0.2 | C22: 6.7823038e-05 | D22: 0.00029364907 | E22: 0.00046447727 | F22: 0.00039620973 | G22: 0.00072260181 | H22: -0.00046606187 | I22: -0.00047623241 | J22: 0.00078614679 | K22: 0.0010225032 | L22: -0.00049033809
A23: r | B23: 0.3 | C23: 9.289232e-05 | D23: 0.00074835032 | E23: 0.000431652 | F23: 0.0010373379 | G23: 0.00024355543 | H23: -0.0012510978 | I23: -0.00045674136 | J23: -0.00050306265 | K23: -0.00059257227 | L23: -0.0016821885
A24: r | B24: 0.4 | C24: -0.00091552723 | D24: -0.00061271088 | E24: -0.00024257445 | F24: -9.8175855e-05 | G24: 1.0692448e-05 | H24: -0.0011986825 | I24: -0.00078931736 | J24: 0.00018148592 | K24: -0.00091171747 | L24: -0.0012236329
A25: r | B25: 0.8 | C25: -0.00047934719 | D25: -0.00034344434 | E25: -0.00043422003 | F25: -0.0010053406 | G25: -0.0019409081 | H25: -0.0016600565 | I25: -4.5871076e-05 | J25: -3.252472e-05 | K25: -0.0038422401 | L25: -0.0048900811
A26: r | B26: 1.2 | C26: -0.00070282198 | D26: -4.8950729e-05 | E26: 4.7378837e-06 | F26: -0.00030806016 | G26: -0.00026229399 | H26: -0.00017036537 | I26: -0.00064526071 | J26: -0.00087896572 | K26: -0.0058879857 | L26: -0.0077544521
A27: r | B27: 1.6 | C27: -0.00031105339 | D27: -0.00025892005 | E27: -0.00031606765 | F27: 1.0546822e-05 | G27: 0.00017670464 | H27: -0.0005856575 | I27: -0.00055399254 | J27: -0.0011343608 | K27: -0.0085067423 | L27: -0.0083755688
A30: <Delta.v_1*Delta.v_3>
A31: t | B31: delta_t | C31: 0 | D31: 0.05 | E31: 0.1 | F31: 0.15 | G31: 0.5 | H31: 1 | I31: 1.5 | J31: 2.5 | K31: 5 | L31: 7.5
A32: r | B32: 0 | C32: 0 | D32: 9.579609e-05 | E32: 0.00086888472 | F32: 0.00083328873 | G32: 0.0062181469 | H32: 0.013771535 | I32: 0.016877742 | J32: 0.01499038 | K32: 0.016309369 | L32: 0.016970039
A33: r | B33: 0.1 | C33: -6.7138417e-05 | D33: -0.00019401504 | E33: 0.00032665242 | F33: 0.00071748829 | G33: 0.0053069222 | H33: 0.013286098 | I33: 0.017809197 | J33: 0.014761798 | K33: 0.017176887 | L33: 0.016772762
A34: r | B34: 0.2 | C34: -0.0012880184 | D34: -0.0010694498 | E34: -1.8585052e-05 | F34: 0.0011195789 | G34: 0.0057371574 | H34: 0.013760639 | I34: 0.017648448 | J34: 0.014485033 | K34: 0.017185301 | L34: 0.017846407
A35: r | B35: 0.3 | C35: -0.00048314304 | D35: -0.00051908707 | E35: -0.00029155733 | F35: 0.00088213395 | G35: 0.00558675 | H35: 0.013283087 | I35: 0.017228432 | J35: 0.013626791 | K35: 0.017526247 | L35: 0.017003647
A36: r | B36: 0.4 | C36: -0.00099103982 | D36: -9.8112159e-05 | E36: 0.00042488152 | F36: 0.0010163234 | G36: 0.0062836627 | H36: 0.013958246 | I36: 0.01678013 | J36: 0.013965189 | K36: 0.018343619 | L36: 0.01593756
A37: r | B37: 0.8 | C37: 0.00061206901 | D37: 0.0015442776 | E37: 0.0021012239 | F37: 0.0019883478 | G37: 0.0057101295 | H37: 0.01247089 | I37: 0.015862799 | J37: 0.013660646 | K37: 0.019488772 | L37: 0.015129954
A38: r | B38: 1.2 | C38: 0.0016732208 | D38: 0.002452432 | E38: 0.003249016 | F38: 0.0032274632 | G38: 0.0074182236 | H38: 0.010564584 | I38: 0.015326015 | J38: 0.013608817 | K38: 0.019533701 | L38: 0.012649859
A39: r | B39: 1.6 | C39: 0.0022396471 | D39: 0.0027290701 | E39: 0.0026347068 | F39: 0.0034713395 | G39: 0.0056765078 | H39: 0.0093832395 | I39: 0.012178014 | J39: 0.01150969 | K39: 0.016114965 | L39: 0.0095686216
A42: <Delta.v_2*Delta.v_1>
A43: t | B43: delta_t | C43: 0 | D43: 0.05 | E43: 0.1 | F43: 0.15 | G43: 0.5 | H43: 1 | I43: 1.5 | J43: 2.5 | K43: 5 | L43: 7.5
A44: r | B44: 0 | C44: 0 | D44: 0.00013086382 | E44: 0.00010392525 | F44: 0.00034423858 | G44: -0.0012385082 | H44: -0.00031679209 | I44: -0.00052311201 | J44: -3.563155e-05 | K44: -0.000185299 | L44: 0.0013500011
A45: r | B45: 0.1 | C45: -0.00011159745 | D45: 0.00017320722 | E45: 0.00071580324 | F45: 0.00067173333 | G45: -0.00059927026 | H45: -0.00032978079 | I45: 0.00063177631 | J45: -0.00014274958 | K45: -0.00069430045 | L45: -0.00084604313
A46: r | B46: 0.2 | C46: 0.00033354487 | D46: 0.00088263557 | E46: 0.00035664521 | F46: 0.00043418855 | G46: 0.00013115632 | H46: 0.00030469301 | I46: 5.5219319e-05 | J46: 2.5342618e-05 | K46: -0.00062749466 | L46: -0.0024473425
A47: r | B47: 0.3 | C47: 0.00081214992 | D47: 0.00048612347 | E47: 0.00054824263 | F47: 0.00086173737 | G47: 0.00089863759 | H47: 0.00058084462 | I47: 0.00019064268 | J47: 0.00055243864 | K47: -0.0010767266 | L47: -0.0037516594
A48: r | B48: 0.4 | C48: 0.00160152 | D48: 0.0012101422 | E48: 0.0009675891 | F48: 0.00049949018 | G48: 0.00094881808 | H48: 0.0013079269 | I48: -7.6209991e-05 | J48: 0.0001673116 | K48: -0.0019563443 | L48: -0.0044563945
A49: r | B49: 0.8 | C49: 0.0015445047 | D49: 0.0012810813 | E49: 0.0012316458 | F49: 0.0018450083 | G49: 0.00036234353 | H49: 0.0014502105 | I49: 0.00099530809 | J49: 5.7054322e-05 | K49: -0.0041705799 | L49: -0.0065655621
A50: r | B50: 1.2 | C50: 0.0020870614 | D50: 0.0016559356 | E50: 0.0018120294 | F50: 0.00186827 | G50: 0.001097779 | H50: 0.0019141687 | I50: -0.00018705059 | J50: -0.001315821 | K50: -0.0071996584 | L50: -0.0075389558
...

Sheet _3_0
A1: Nmb_of_pts | B1: 150000, time_0 | C1: 0.2
A6: <Delta.v_1*Delta.v_1>
A7: t | B7: delta_t | C7: 0 | D7: 0.05 | E7: 0.1 | F7: 0.15 | G7: 0.5 | H7: 1 | I7: 1.5 | J7: 2.5 | K7: 5 | L7: 7.5
A8: r | B8: 0 | C8: 0 | D8: -0.026569264 | E8: -0.045864089 | F8: -0.059457918 | G8: -0.1142157 | H8: -0.16448996 | I8: -0.20776877 | J8: -0.27081978 | K8: -0.30763218 | L8: -0.36973942
A9: r | B9: 0.1 | C9: -0.040014031 | D9: -0.044689607 | E9: -0.054668032 | F9: -0.06505731 | G9: -0.11710471 | H9: -0.16570344 | I9: -0.20851873 | J9: -0.27032933 | K9: -0.3072653 | L9: -0.37035869
A10: r | B10: 0.2 | C10: -0.069723528 | D10: -0.070927604 | E10: -0.074374554 | F10: -0.079872144 | G10: -0.12200617 | H10: -0.16925982 | I10: -0.20992929 | J10: -0.27083052 | K10: -0.30789386 | L10: -0.3704565
A11: r | B11: 0.3 | C11: -0.093486067 | D11: -0.094393234 | E11: -0.095949595 | F11: -0.09845959 | G11: -0.12971305 | H11: -0.1734614 | I11: -0.21240056 | J11: -0.27284855 | K11: -0.30877129 | L11: -0.37084692
A12: r | B12: 0.4 | C12: -0.11550375 | D12: -0.11537002 | E12: -0.11591876 | F12: -0.11715549 | G12: -0.14086692 | H12: -0.17989763 | I12: -0.21732518 | J12: -0.27498793 | K12: -0.31018982 | L12: -0.37136187
A13: r | B13: 0.8 | C13: -0.18573544 | D13: -0.18559674 | E13: -0.18648139 | F13: -0.18695503 | G13: -0.19425527 | H13: -0.21673369 | I13: -0.24095665 | J13: -0.28404054 | K13: -0.31991781 | L13: -0.37609103
A14: r | B14: 1.2 | C14: -0.2418678 | D14: -0.242721 | E14: -0.24311024 | F14: -0.24413195 | G14: -0.24777492 | H14: -0.25772744 | I14: -0.27464682 | J14: -0.30116265 | K14: -0.33377319 | L14: -0.38402913
A15: r | B15: 1.6 | C15: -0.28798552 | D15: -0.28770081 | E15: -0.28776463 | F15: -0.28839699 | G15: -0.29123889 | H15: -0.29848163 | I15: -0.30564881 | J15: -0.32145787 | K15: -0.35148014 | L15: -0.39158749
A18: <Delta.v_1*Delta.v_2>
A19: t | B19: delta_t | C19: 0 | D19: 0.05 | E19: 0.1 | F19: 0.15 | G19: 0.5 | H19: 1 | I19: 1.5 | J19: 2.5 | K19: 5 | L19: 7.5
A20: r | B20: 0 | C20: 0 | D20: -0.00050373462 | E20: 0.00024173982 | F20: -0.0002095385 | G20: -0.0023846698 | H20: -0.0019854837 | I20: -0.00081959353 | J20: -0.00057637588 | K20: 0.00040850948 | L20: -0.00057511035
A21: r | B21: 0.1 | C21: 0.00042403349 | D21: 3.8849922e-05 | E21: -0.00050280593 | F21: -0.00063907541 | G21: -0.0017657793 | H21: -0.0017435583 | I21: -0.00028357793 | J21: -0.0002520238 | K21: 0.00061618612 | L21: -0.0022228564
A22: r | B22: 0.2 | C22: -0.00024872616 | D22: -0.00011783336 | E22: -4.8341656e-05 | F22: -0.00030422935 | G22: -0.0011988813 | H22: -0.001399623 | I22: -0.00060050826 | J22: -0.00017384427 | K22: -0.0010367796 | L22: -0.0030032463
A23: r | B23: 0.3 | C23: -0.00081504161 | D23: -0.00023416899 | E23: -0.00028746064 | F23: -0.00070484069 | G23: -0.00016082998 | H23: -0.00026401246 | I23: -0.00015014967 | J23: 0.00081201996 | K23: -0.0011800891 | L23: -0.0041742737
A24: r | B24: 0.4 | C24: -0.00070322962 | D24: -0.00051094132 | E24: -0.00067397192 | F24: -0.00038371765 | G24: -0.0013623129 | H24: -2.784591e-05 | I24: -0.0003953924 | J24: 0.00044764514 | K24: -0.0014287099 | L24: -0.0050662378
A25: r | B25: 0.8 | C25: 6.5093881e-05 | D25: 0.00010714256 | E25: 4.8941206e-05 | F25: 0.00022318835 | G25: -0.0017763113 | H25: -8.18178e-05 | I25: 0.001152866 | J25: 0.00045057253 | K25: -0.0038599933 | L25: -0.0074825781
A26: r | B26: 1.2 | C26: 0.00056031827 | D26: 0.00019175666 | E26: -0.00041596019 | F26: -0.00071792788 | G26: -0.0003634247 | H26: -0.00034117846 | I26: -0.001540115 | J26: -0.0010387498 | K26: -0.0078150221 | L26: -0.009809198
A27: r | B27: 1.6 | C27: 0.00022518673 | D27: 0.00048086923 | E27: 0.00012897195 | F27: 0.00024350635 | G27: -0.00022334492 | H27: -0.00019198855 | I27: -9.947539e-05 | J27: -0.0033874779 | K27: -0.010514546 | L27: -0.0098426953
A30: <Delta.v_1*Delta.v_3>
A31: t | B31: delta_t | C31: 0 | D31: 0.05 | E31: 0.1 | F31: 0.15 | G31: 0.5 | H31: 1 | I31: 1.5 | J31: 2.5 | K31: 5 | L31: 7.5
A32: r | B32: 0 | C32: 0 | D32: 0.00087335387 | E32: 0.0015033496 | F32: 0.0021152707 | G32: 0.0071456642 | H32: 0.015446415 | I32: 0.018451234 | J32: 0.0162984 | K32: 0.020515358 | L32: 0.019484968
A33: r | B33: 0.1 | C33: 0.0011784922 | D33: 0.0014456916 | E33: 0.00082400701 | F33: 0.0023078797 | G33: 0.0077506405 | H33: 0.015031158 | I33: 0.018197891 | J33: 0.015642365 | K33: 0.019298182 | L33: 0.019304884
A34: r | B34: 0.2 | C34: 0.00026368236 | D34: 0.00030261362 | E34: 0.0019059407 | F34: 0.0021096562 | G34: 0.0078051244 | H34: 0.014979737 | I34: 0.018142592 | J34: 0.01484133 | K34: 0.019920904 | L34: 0.019475716
A35: r | B35: 0.3 | C35: 0.00092580731 | D35: 0.0010053704 | E35: 0.0011659086 | F35: 0.0021547357 | G35: 0.008217988 | H35: 0.014924715 | I35: 0.018401454 | J35: 0.015179011 | K35: 0.019272749 | L35: 0.018208022
A36: r | B36: 0.4 | C36: 0.00053826367 | D36: 0.0014557689 | E36: 0.0018030633 | F36: 0.0036168017 | G36: 0.0078232372 | H36: 0.015563019 | I36: 0.019010674 | J36: 0.016565232 | K36: 0.019526943 | L36: 0.016739226
A37: r | B37: 0.8 | C37: 0.0014022621 | D37: 0.0028318416 | E37: 0.0039495184 | F37: 0.0050901242 | G37: 0.0080460929 | H37: 0.013848218 | I37: 0.01826462 | J37: 0.015190761 | K37: 0.019622771 | L37: 0.015554786
A38: r | B38: 1.2 | C38: 0.0053401181 | D38: 0.0055582679 | E38: 0.0060231229 | F38: 0.0060189275 | G38: 0.0088770245 | H38: 0.013223806 | I38: 0.016671753 | J38: 0.015245302 | K38: 0.01958337 | L38: 0.012661165
A39: r | B39: 1.6 | C39: 0.0034147571 | D39: 0.0044442155 | E39: 0.0053152447 | F39: 0.0061057372 | G39: 0.0080697002 | H39: 0.010838455 | I39: 0.013218401 | J39: 0.012680849 | K39: 0.016216972 | L39: 0.0099032567
A42: <Delta.v_2*Delta.v_1>
A43: t | B43: delta_t | C43: 0 | D43: 0.05 | E43: 0.1 | F43: 0.15 | G43: 0.5 | H43: 1 | I43: 1.5 | J43: 2.5 | K43: 5 | L43: 7.5
A44: r | B44: 0 | C44: 0 | D44: -0.0002803362 | E44: 4.0435422e-06 | F44: 0.00032516383 | G44: 8.2557988e-05 | H44: -0.00012683035 | I44: -6.1772923e-05 | J44: 7.2756109e-06 | K44: -0.0012377534 | L44: 0.0021130694
A45: r | B45: 0.1 | C45: 0.00069203977 | D45: 3.3755142e-05 | E45: 0.0004137249 | F45: 0.00046564723 | G45: 0.00045557395 | H45: -0.0010692168 | I45: -0.00015365043 | J45: -0.00019266182 | K45: -0.0022744375 | L45: 0.00078685462
A46: r | B46: 0.2 | C46: 0.0003750205 | D46: 0.00033220455 | E46: 0.00033021801 | F46: 0.0006970913 | G46: -0.00013989035 | H46: -0.0007212947 | I46: -0.00019668993 | J46: -0.00028310325 | K46: -0.0016112441 | L46: -0.00063388885
A47: r | B47: 0.3 | C47: 0.00096072975 | D47: 0.0010503303 | E47: 0.00058789592 | F47: 0.00069350021 | G47: -0.00015424826 | H47: -0.00081119485 | I47: -0.00044297035 | J47: -0.00029419192 | K47: -0.0013660002 | L47: -0.0022822368
A48: r | B48: 0.4 | C48: 0.0010606812 | D48: 0.0011761287 | E48: 0.001591199 | F48: 0.00076273745 | G48: -9.1384864e-05 | H48: -0.00032485441 | I48: -0.00024529632 | J48: 0.00026813956 | K48: -0.0022761581 | L48: -0.0034276473
A49: r | B49: 0.8 | C49: 0.0016082136 | D49: 0.001156063 | E49: 0.0015104634 | F49: 0.0014291297 | G49: 8.2677929e-05 | H49: -0.00076852193 | I49: -0.00064619969 | J49: -0.0005864136 | K49: -0.0037000533 | L49: -0.0055188763
A50: r | B50: 1.2 | C50: 0.0014598902 | D50: 0.0015564089 | E50: 0.0014767108 | F50: 0.0018989274 | G50: 0.0013139556 | H50: 3.9520308e-05 | I50: -0.00065117207 | J50: -0.0034331047 | K50: -0.0077666499 | L50: -0.0093147124
...

Sheet _1_1
A1: Nmb_of_pts | B1: 150000, time_0 | C1: 0.2
A6: <Delta.v_1*Delta.v_1>
A7: t | B7: delta_t | C7: 0 | D7: 0.03 | E7: 0.05999999 | F7: 0.08999999 | G7: 0.3 | H7: 0.6 | I7: 0.9 | J7: 2 | K7: 4 | L7: 6
A8: r | B8: 0 | C8: 0 | D8: -0.014770935 | E8: -0.03033214 | F8: -0.041991657 | G8: -0.088992036 | H8: -0.12620603 | I8: -0.1572896 | J8: -0.24364802 | K8: -0.29176135 | L8: -0.3320396
A9: r | B9: 0.1 | C9: -0.039968361 | D9: -0.041775668 | E9: -0.046816165 | F9: -0.053274794 | G9: -0.091695581 | H9: -0.12817757 | I9: -0.15893635 | J9: -0.24353764 | K9: -0.29178391 | L9: -0.33240877
A10: r | B10: 0.2 | C10: -0.069764018 | D10: -0.070117674 | E10: -0.071912054 | F10: -0.074088476 | G10: -0.10007807 | H10: -0.13276825 | I10: -0.16170107 | J10: -0.24577445 | K10: -0.29272688 | L10: -0.33279714
A11: r | B11: 0.3 | C11: -0.093560306 | D11: -0.093810388 | E11: -0.094461775 | F11: -0.095600523 | G11: -0.1126389 | H11: -0.13993686 | I11: -0.16699444 | J11: -0.24747036 | K11: -0.29342684 | L11: -0.33309209
A12: r | B12: 0.4 | C12: -0.11537269 | D12: -0.11610819 | E12: -0.11636796 | F12: -0.11680612 | G12: -0.12710391 | H12: -0.15071181 | I12: -0.17489575 | J12: -0.25099476 | K12: -0.29576912 | L12: -0.33355822
A13: r | B13: 0.8 | C13: -0.18602622 | D13: -0.18565708 | E13: -0.18574596 | F13: -0.18624344 | G13: -0.18984459 | H13: -0.19975263 | I13: -0.21337907 | J13: -0.26804118 | K13: -0.30611465 | L13: -0.34184807
A14: r | B14: 1.2 | C14: -0.24325794 | D14: -0.24367374 | E14: -0.24394557 | F14: -0.24377385 | G14: -0.24589809 | H14: -0.2495736 | I14: -0.25565395 | J14: -0.28942925 | K14: -0.32177012 | L14: -0.35225299
A15: r | B15: 1.6 | C15: -0.28948091 | D15: -0.28917539 | E15: -0.28912104 | F15: -0.28944381 | G15: -0.28963693 | H15: -0.29276295 | I15: -0.29598833 | J15: -0.31469383 | K15: -0.33989933 | L15: -0.36567038
A18: <Delta.v_1*Delta.v_2>
A19: t | B19: delta_t | C19: 0 | D19: 0.03 | E19: 0.05999999 | F19: 0.08999999 | G19: 0.3 | H19: 0.6 | I19: 0.9 | J19: 2 | K19: 4 | L19: 6
A20: r | B20: 0 | C20: 0 | D20: -0.00038643064 | E20: -0.00045451755 | F20: -0.00096448347 | G20: -0.00091108639 | H20: -0.00035498613 | I20: -0.00080073559 | J20: -0.00095509076 | K20: 0.0014607902 | L20: 0.0010685864
A21: r | B21: 0.1 | C21: -0.0013235724 | D21: -0.0015108501 | E21: -0.0011790778 | F21: -0.00081052762 | G21: -0.0012659327 | H21: -0.0012608781 | I21: -0.00091476523 | J21: -0.0013511345 | K21: 0.0005538991 | L21: -4.5963073e-06
A22: r | B22: 0.2 | C22: -0.0009690787 | D22: -0.00072459322 | E22: -0.00053594211 | F22: -0.00080908774 | G22: -0.00049663527 | H22: -0.00083821416 | I22: 0.00034240646 | J22: -0.0018159126 | K22: 0.00062338368 | L22: -0.00092299007
A23: r | B23: 0.3 | C23: -0.0006230587 | D23: -0.00091424717 | E23: -0.0007633599 | F23: -0.00080922505 | G23: -0.0008033894 | H23: -0.0017420505 | I23: -0.00082758188 | J23: -0.0019003128 | K23: -0.00018748908 | L23: -0.0017069483
A24: r | B24: 0.4 | C24: 1.7647458e-05 | D24: -0.00010030656 | E24: -0.00062383654 | F24: -0.00097430022 | G24: -0.00071654657 | H24: -0.0022741624 | I24: -0.0011974238 | J24: -0.0018794971 | K24: -0.0009834603 | L24: -0.0030213997
A25: r | B25: 0.8 | C25: -0.00027626283 | D25: -2.8400591e-05 | E25: -0.00019172466 | F25: -0.00018577691 | G25: -0.00051024679 | H25: -0.00013009127 | I25: -0.00049869187 | J25: -0.00013636399 | K25: -0.0017137412 | L25: -0.0045114556
A26: r | B26: 1.2 | C26: 9.2477023e-06 | D26: -0.00059689729 | E26: -0.00069553774 | F26: -0.00082704691 | G26: -0.00022899285 | H26: -0.0013591897 | I26: -0.0015205085 | J26: -0.0015287496 | K26: -0.0056387244 | L26: -0.0080483232
A27: r | B27: 1.6 | C27: 0.0017826585 | D27: 0.0019311044 | E27: 0.0017204784 | F27: 0.0014515896 | G27: 0.0010641523 | H27: 0.00095567429 | I27: 0.00051506406 | J27: -0.0021132909 | K27: -0.0070629276 | L27: -0.0093103101
A30: <Delta.v_1*Delta.v_3>
A31: t | B31: delta_t | C31: 0 | D31: 0.03 | E31: 0.05999999 | F31: 0.08999999 | G31: 0.3 | H31: 0.6 | I31: 0.9 | J31: 2 | K31: 4 | L31: 6
A32: r | B32: 0 | C32: 0 | D32: 0.00047950438 | E32: 0.00073534103 | F32: 0.0010405326 | G32: 0.0042571202 | H32: 0.0080281756 | I32: 0.013116196 | J32: 0.016275176 | K32: 0.014798207 | L32: 0.021214766
A33: r | B33: 0.1 | C33: 0.00042723297 | D33: 0.00054265834 | E33: 0.0012327731 | F33: 0.0010047091 | G33: 0.0040582205 | H33: 0.0087551325 | I33: 0.013440736 | J33: 0.016694593 | K33: 0.015701546 | L33: 0.02123505
A34: r | B34: 0.2 | C34: -0.0004362642 | D34: -0.00018024281 | E34: 0.00052552344 | F34: 0.0010779307 | G34: 0.0050595053 | H34: 0.0098023341 | I34: 0.013552755 | J34: 0.016972407 | K34: 0.015259996 | L34: 0.022131003
A35: r | B35: 0.3 | C35: -0.0013588912 | D35: -0.00051013861 | E35: 6.181235e-05 | F35: 0.00010385235 | G35: 0.0049473676 | H35: 0.009709775 | I35: 0.013141252 | J35: 0.017559842 | K35: 0.015982709 | L35: 0.021771586
A36: r | B36: 0.4 | C36: -0.00030325443 | D36: -0.00013053082 | E36: -0.00012870797 | F36: 0.0001367035 | G36: 0.0053522757 | H36: 0.010253219 | I36: 0.013631671 | J36: 0.017609739 | K36: 0.017085501 | L36: 0.021484671
A37: r | B37: 0.8 | C37: 0.0016555991 | D37: 0.0017009228 | E37: 0.0020521487 | F37: 0.0024272345 | G37: 0.0049326079 | H37: 0.0088224176 | I37: 0.013350463 | J37: 0.016642618 | K37: 0.018002346 | L37: 0.020792633
A38: r | B38: 1.2 | C38: 0.0028116907 | D38: 0.0033615424 | E38: 0.00397467 | F38: 0.0043399115 | G38: 0.0069261846 | H38: 0.0093422467 | I38: 0.011634182 | J38: 0.016924929 | K38: 0.016677579 | L38: 0.01772256
A39: r | B39: 1.6 | C39: 0.0039038871 | D39: 0.0036880746 | E39: 0.0037609141 | F39: 0.0041343837 | G39: 0.0063337454 | H39: 0.0088292405 | I39: 0.010434406 | J39: 0.013134188 | K39: 0.014589391 | L39: 0.01560986
A42: <Delta.v_2*Delta.v_1>
A43: t | B43: delta_t | C43: 0 | D43: 0.03 | E43: 0.05999999 | F43: 0.08999999 | G43: 0.3 | H43: 0.6 | I43: 0.9 | J43: 2 | K43: 4 | L43: 6
A44: r | B44: 0 | C44: 0 | D44: -0.00013525969 | E44: -0.0003260194 | F44: -0.00075906109 | G44: 0.00042306991 | H44: -0.00052668729 | I44: 0.00067637421 | J44: -0.0017234216 | K44: -0.00031709439 | L44: 0.00068825516
A45: r | B45: 0.1 | C45: -0.00048263496 | D45: -0.0003096317 | E45: -0.00047443027 | F45: -0.00025081701 | G45: -1.2614271e-05 | H45: -0.0005407265 | I45: -0.0007588081 | J45: -0.0015911543 | K45: -0.00088810763 | L45: 0.00079780894
A46: r | B46: 0.2 | C46: -0.00010233363 | D46: 0.00034769133 | E46: 0.00037693088 | F46: 0.00058696378 | G46: 2.5886971e-05 | H46: -0.00050705928 | I46: -0.0011286889 | J46: -0.0021310593 | K46: -0.0012882806 | L46: -0.00068175626
A47: r | B47: 0.3 | C47: 0.00068552872 | D47: 0.00049407185 | E47: 0.00047157922 | F47: 0.00021141794 | G47: 6.0519094e-05 | H47: -0.0003878997 | I47: -0.0012144302 | J47: -0.0029320303 | K47: -0.0016325713 | L47: -0.0015784592
A48: r | B48: 0.4 | C48: 0.001130882 | D48: 0.0010366973 | E48: 0.0011263286 | F48: 0.00075691548 | G48: 0.00048250796 | H48: -0.000169961 | I48: -0.0016794534 | J48: -0.0030519049 | K48: -0.0010589479 | L48: -0.0028282721
A49: r | B49: 0.8 | C49: 0.00047077065 | D49: 0.00038403916 | E49: 0.00027561149 | F49: 0.00060308117 | G49: -0.00028038474 | H49: -0.00025486416 | I49: -0.00072392641 | J49: -0.0020274905 | K49: -0.0045273418 | L49: -0.0040944217
A50: r | B50: 1.2 | C50: -2.6658388e-05 | D50: 0.00022066838 | E50: 8.2291985e-05 | F50: 9.4949146e-06 | G50: -0.0013830833 | H50: -0.00058140836 | I50: -0.0014355121 | J50: -0.002436226 | K50: -0.0071380616 | L50: -0.0071877477
...

Sheet _2_1
A1: Nmb_of_pts | B1: 150000, time_0 | C1: 0.2
A6: <Delta.v_1*Delta.v_1>
A7: t | B7: delta_t | C7: 0 | D7: 0.03 | E7: 0.05999999 | F7: 0.08999999 | G7: 0.3 | H7: 0.6 | I7: 0.9 | J7: 2 | K7: 4 | L7: 6
A8: r | B8: 0 | C8: 0 | D8: -0.015665235 | E8: -0.031613133 | F8: -0.042941719 | G8: -0.088992091 | H8: -0.12642095 | I8: -0.15674157 | J8: -0.24143126 | K8: -0.2865481 | L8: -0.32791143
A9: r | B9: 0.1 | C9: -0.040750606 | D9: -0.043098435 | E9: -0.048095937 | F9: -0.05376751 | G9: -0.092146346 | H9: -0.1288555 | I9: -0.15736457 | J9: -0.24173972 | K9: -0.28687106 | L9: -0.32855963
A10: r | B10: 0.2 | C10: -0.071327322 | D10: -0.071747892 | E10: -0.073341928 | F10: -0.075382381 | G10: -0.10035611 | H10: -0.13383946 | I10: -0.16131022 | J10: -0.24332919 | K10: -0.28858589 | L10: -0.32955113
A11: r | B11: 0.3 | C11: -0.094755615 | D11: -0.095030404 | E11: -0.096060495 | F11: -0.09697528 | G11: -0.11316404 | H11: -0.14085897 | I11: -0.16705437 | J11: -0.244888 | K11: -0.28965985 | L11: -0.33044469
A12: r | B12: 0.4 | C12: -0.11629729 | D12: -0.11643731 | E12: -0.1173824 | F12: -0.11759275 | G12: -0.12713857 | H12: -0.15022158 | I12: -0.17344181 | J12: -0.24780047 | K12: -0.2912511 | L12: -0.33138548
A13: r | B13: 0.8 | C13: -0.18540033 | D13: -0.18525661 | E13: -0.18572996 | F13: -0.18571081 | G13: -0.18988776 | H13: -0.19751062 | I13: -0.21076724 | J13: -0.26560275 | K13: -0.30181354 | L13: -0.34033954
A14: r | B14: 1.2 | C14: -0.24201075 | D14: -0.24208514 | E14: -0.24248277 | F14: -0.24207329 | G14: -0.24383833 | H14: -0.24726327 | I14: -0.25379329 | J14: -0.28703707 | K14: -0.31832728 | L14: -0.35221859
A15: r | B15: 1.6 | C15: -0.28723746 | D15: -0.28703577 | E15: -0.28700081 | F15: -0.28692728 | G15: -0.28835328 | H15: -0.29026812 | I15: -0.29396477 | J15: -0.3116576 | K15: -0.3358578 | L15: -0.36508559
A18: <Delta.v_1*Delta.v_2>
A19: t | B19: delta_t | C19: 0 | D19: 0.03 | E19: 0.05999999 | F19: 0.08999999 | G19: 0.3 | H19: 0.6 | I19: 0.9 | J19: 2 | K19: 4 | L19: 6
A20: r | B20: 0 | C20: 0 | D20: 0.00012368264 | E20: 0.00078854418 | F20: 0.0010412637 | G20: 0.00014541177 | H20: 4.0354802e-06 | I20: 5.3361363e-05 | J20: 0.0013324876 | K20: -0.0023746974 | L20: 0.00079802591
A21: r | B21: 0.1 | C21: 0.0011111972 | D21: 0.0012178689 | E21: 0.00073529662 | F21: 0.00060381805 | G21: 0.00026757711 | H21: 0.00086047298 | I21: 0.00088577461 | J21: 0.002005168 | K21: -0.0014484758 | L21: -2.124619e-05
A22: r | B22: 0.2 | C22: 0.0013451325 | D22: 0.001076756 | E22: 0.0013004025 | F22: 0.0012754412 | G22: 0.00035799724 | H22: 0.00057668514 | I22: 0.00088324355 | J22: 0.0010676484 | K22: -0.0012363424 | L22: -0.00068427126
A23: r | B23: 0.3 | C23: 0.00078311622 | D23: 0.00084623325 | E23: 0.00054145074 | F23: 0.00011263363 | G23: 0.00024174611 | H23: 0.00020182536 | I23: 0.00079540903 | J23: 0.00030520615 | K23: -0.0012629138 | L23: -0.0021188367
A24: r | B24: 0.4 | C24: 0.00040967015 | D24: 0.00028152289 | E24: -0.0002708648 | F24: 0.00042614559 | G24: 0.00044652668 | H24: 0.00060815401 | I24: -0.00012860777 | J24: 3.7971988e-05 | K24: -0.0016377201 | L24: -0.0034247541
A25: r | B25: 0.8 | C25: 0.00076632883 | D25: 0.00045782014 | E25: 0.00011227689 | F25: 0.00016678795 | G25: -0.00025619734 | H25: -0.00065258162 | I25: 0.00053792493 | J25: 0.0012469643 | K25: -0.0025863061 | L25: -0.0065808498
A26: r | B26: 1.2 | C26: 0.00017685139 | D26: 0.00071040628 | E26: 0.00037626396 | F26: 0.00046496111 | G26: 0.00014938325 | H26: 0.00027718397 | I26: 0.00056869072 | J26: -0.0015151709 | K26: -0.0043913963 | L26: -0.0096146131
A27: r | B27: 1.6 | C27: -0.0011282306 | D27: -0.0011706808 | E27: -0.0007922657 | F27: -0.0002991945 | G27: 0.00011493415 | H27: 0.00041982353 | I27: -0.00045818569 | J27: -0.0026378136 | K27: -0.0077176283 | L27: -0.011967226
A30: <Delta.v_1*Delta.v_3>
A31: t | B31: delta_t | C31: 0 | D31: 0.03 | E31: 0.05999999 | F31: 0.08999999 | G31: 0.3 | H31: 0.6 | I31: 0.9 | J31: 2 | K31: 4 | L31: 6
A32: r | B32: 0 | C32: 0 | D32: 0.00043865405 | E32: 0.00012294465 | F32: 7.6003852e-05 | G32: 0.0027008324 | H32: 0.0066836111 | I32: 0.013333267 | J32: 0.015000279 | K32: 0.014978446 | L32: 0.01899007
A33: r | B33: 0.1 | C33: -0.00025293988 | D33: -0.00021504669 | E33: 5.7085267e-05 | F33: 0.00059529403 | G33: 0.0026502537 | H33: 0.0074776281 | I33: 0.012648189 | J33: 0.015617302 | K33: 0.014236505 | L33: 0.018448062
A34: r | B34: 0.2 | C34: -0.00045730407 | D34: -1.7820916e-05 | E34: 0.0003880843 | F34: 0.00037311187 | G34: 0.0026197185 | H34: 0.0075810258 | I34: 0.013161389 | J34: 0.016407252 | K34: 0.015810751 | L34: 0.017756203
A35: r | B35: 0.3 | C35: -0.00041088362 | D35: -0.00036211783 | E35: -0.00015717875 | F35: -4.7159889e-05 | G35: 0.0030942138 | H35: 0.0071526562 | I35: 0.011583923 | J35: 0.016494651 | K35: 0.016230162 | L35: 0.018123813
A36: r | B36: 0.4 | C36: -0.00036373654 | D36: -2.703223e-06 | E36: 0.00019161781 | F36: 0.00093789083 | G36: 0.0027106937 | H36: 0.0078359325 | I36: 0.011721039 | J36: 0.015895148 | K36: 0.016328431 | L36: 0.01892528
A37: r | B37: 0.8 | C37: 0.00037685448 | D37: 0.00071789193 | E37: 0.0015354513 | F37: 0.0024354003 | G37: 0.0041472738 | H37: 0.0065464205 | I37: 0.010874519 | J37: 0.015018335 | K37: 0.015262287 | L37: 0.017888937
A38: r | B38: 1.2 | C38: 0.00057160852 | D38: 0.0011307539 | E38: 0.0020884206 | F38: 0.0021792151 | G38: 0.0040213644 | H38: 0.0070280511 | I38: 0.0092063577 | J38: 0.01441969 | K38: 0.012367874 | L38: 0.01645787
A39: r | B39: 1.6 | C39: 0.0020939685 | D39: 0.0023364119 | E39: 0.0024066264 | F39: 0.0027500975 | G39: 0.0045209274 | H39: 0.0061537428 | I39: 0.0088288925 | J39: 0.011767959 | K39: 0.010263285 | L39: 0.012349838
A42: <Delta.v_2*Delta.v_1>
A43: t | B43: delta_t | C43: 0 | D43: 0.03 | E43: 0.05999999 | F43: 0.08999999 | G43: 0.3 | H43: 0.6 | I43: 0.9 | J43: 2 | K43: 4 | L43: 6
A44: r | B44: 0 | C44: 0 | D44: -0.00053142109 | E44: -0.00049153108 | F44: -0.00022055235 | G44: -0.0011473899 | H44: -0.00013623929 | I44: 0.00043620141 | J44: -3.9244091e-05 | K44: -0.00034099096 | L44: 0.00015707105
A45: r | B45: 0.1 | C45: 8.4804698e-05 | D45: -5.3027532e-05 | E45: -0.00017808733 | F45: -0.00044797533 | G45: -0.0007238235 | H45: 6.6059472e-05 | I45: 0.00091047345 | J45: -0.00028325011 | K45: -0.0010043244 | L45: -0.00081234877
A46: r | B46: 0.2 | C46: 0.00021079145 | D46: 0.0004461582 | E46: 0.00046780772 | F46: 0.0003081602 | G46: -0.0002338989 | H46: 0.00015374957 | I46: 0.0010963096 | J46: -0.00074099716 | K46: -0.0011569113 | L46: -0.0018033902
A47: r | B47: 0.3 | C47: 0.00091968948 | D47: 0.0011135642 | E47: 0.00097477652 | F47: 0.00026921718 | G47: 0.00036891585 | H47: 0.00021382688 | I47: 0.00060511598 | J47: -0.00046909977 | K47: -0.0020915113 | L47: -0.0029750365
A48: r | B48: 0.4 | C48: 0.0014046888 | D48: 0.0014148449 | E48: 0.0016257825 | F48: 0.0014999923 | G48: 0.00064141873 | H48: -0.00051141659 | I48: 0.00070819019 | J48: -0.00089896464 | K48: -0.0029168628 | L48: -0.0046024423
A49: r | B49: 0.8 | C49: 0.0007114079 | D49: 0.00079797302 | E49: 0.0010543428 | F49: 0.0014017569 | G49: 0.001694562 | H49: 6.8037985e-05 | I49: -0.00034377959 | J49: -0.0018918393 | K49: -0.0042358817 | L49: -0.0065896455
A50: r | B50: 1.2 | C50: 0.00086826094 | D50: 0.00050361325 | E50: 0.00089822901 | F50: 0.0013768812 | G50: 0.00064282027 | H50: -0.00030927414 | I50: -0.00099082355 | J50: -0.0023692973 | K50: -0.0072558125 | L50: -0.0094063248
...

Sheet _3_1
A1: Nmb_of_pts | B1: 150000, time_0 | C1: 0.2
A6: <Delta.v_1*Delta.v_1>
A7: t | B7: delta_t | C7: 0 | D7: 0.03 | E7: 0.05999999 | F7: 0.08999999 | G7: 0.3 | H7: 0.6 | I7: 0.9 | J7: 2 | K7: 4 | L7: 6
A8: r | B8: 0 | C8: 0 | D8: -0.014840116 | E8: -0.03103428 | F8: -0.042872133 | G8: -0.089947035 | H8: -0.12725131 | I8: -0.15643484 | J8: -0.24130564 | K8: -0.28894024 | L8: -0.33009091
A9: r | B9: 0.1 | C9: -0.040179312 | D9: -0.041745422 | E9: -0.04665085 | F9: -0.053102839 | G9: -0.092705969 | H9: -0.13008137 | I9: -0.15747864 | J9: -0.24193833 | K9: -0.28918408 | L9: -0.32918129
A10: r | B10: 0.2 | C10: -0.069543975 | D10: -0.070727191 | E10: -0.071861404 | F10: -0.074087693 | G10: -0.10055132 | H10: -0.13413084 | I10: -0.16164734 | J10: -0.24402948 | K10: -0.29064229 | L10: -0.33055347
A11: r | B11: 0.3 | C11: -0.093990858 | D11: -0.094298497 | E11: -0.095246968 | F11: -0.096609735 | G11: -0.11235548 | H11: -0.14168323 | I11: -0.16720186 | J11: -0.24652282 | K11: -0.29161895 | L11: -0.331277
A12: r | B12: 0.4 | C12: -0.11514588 | D12: -0.11511153 | E12: -0.11535272 | F12: -0.11628551 | G12: -0.12715824 | H12: -0.15133294 | I12: -0.17426939 | J12: -0.24992435 | K12: -0.29312382 | L12: -0.3330737
A13: r | B13: 0.8 | C13: -0.18710624 | D13: -0.18704963 | E13: -0.18743717 | F13: -0.18739374 | G13: -0.18947553 | H13: -0.19980378 | I13: -0.21273728 | J13: -0.2686455 | K13: -0.30431601 | L13: -0.34102808
A14: r | B14: 1.2 | C14: -0.24261945 | D14: -0.24285826 | E14: -0.24294788 | F14: -0.24350207 | G14: -0.24697016 | H14: -0.25006035 | I14: -0.25677466 | J14: -0.29082541 | K14: -0.32088903 | L14: -0.35217172
A15: r | B15: 1.6 | C15: -0.28881713 | D15: -0.288755 | E15: -0.28877659 | F15: -0.28969482 | G15: -0.29118745 | H15: -0.29489773 | I15: -0.29852354 | J15: -0.31592778 | K15: -0.33820498 | L15: -0.36654536
A18: <Delta.v_1*Delta.v_2>
A19: t | B19: delta_t | C19: 0 | D19: 0.03 | E19: 0.05999999 | F19: 0.08999999 | G19: 0.3 | H19: 0.6 | I19: 0.9 | J19: 2 | K19: 4 | L19: 6
A20: r | B20: 0 | C20: 0 | D20: 0.00016443565 | E20: 0.00020128643 | F20: 0.00035769959 | G20: 0.0002326733 | H20: 0.00026893812 | I20: 0.0011047964 | J20: 0.0022047454 | K20: 0.0017191097 | L20: 0.0017404166
A21: r | B21: 0.1 | C21: -0.00088728605 | D21: -0.00036259317 | E21: -0.00013575547 | F21: 0.00059940803 | G21: 0.0001149574 | H21: 0.00082466035 | I21: 0.00062942409 | J21: 0.0011364253 | K21: 0.0019687202 | L21: 0.00070698422
A22: r | B22: 0.2 | C22: 0.00037488564 | D22: 0.00065236951 | E22: 0.00079212943 | F22: 0.00083355204 | G22: 0.00093707683 | H22: 0.00069716986 | I22: 0.00089774763 | J22: 0.0010440388 | K22: 0.0021140771 | L22: -9.1711343e-05
A23: r | B23: 0.3 | C23: 0.00043925931 | D23: 0.0008830056 | E23: 0.00083705855 | F23: 0.0013099096 | G23: 0.0011266685 | H23: 0.00096459563 | I23: 0.00046851426 | J23: 0.0011124008 | K23: 0.00075413588 | L23: -4.2891108e-05
A24: r | B24: 0.4 | C24: 0.00071773016 | D24: 0.0011819337 | E24: 0.0016377789 | F24: 0.0016000461 | G24: 0.001734436 | H24: 0.00063611969 | I24: 0.00066321697 | J24: 0.00044523488 | K24: -9.7836795e-05 | L24: -0.00022246667
A25: r | B25: 0.8 | C25: 0.00083140475 | D25: 0.00036559649 | E25: 0.00039415313 | F25: 0.00023589488 | G25: 0.00061681007 | H25: 0.0003864908 | I25: -0.00028259162 | J25: -0.00079323913 | K25: -0.0015161439 | L25: -0.0042289228
A26: r | B26: 1.2 | C26: -5.2913435e-05 | D26: -0.00022787114 | E26: 0.00017544317 | F26: 0.00040186544 | G26: -0.00073801874 | H26: -0.00079780943 | I26: 5.7198903e-06 | J26: -6.5655525e-05 | K26: -0.0042593228 | L26: -0.0083335413
A27: r | B27: 1.6 | C27: -7.7036062e-06 | D27: -0.00025500071 | E27: -1.7106164e-06 | F27: 4.8149476e-05 | G27: -0.00017741312 | H27: -0.00040173237 | I27: -0.00062194461 | J27: -0.001615325 | K27: -0.0081663004 | L27: -0.0091394627
A30: <Delta.v_1*Delta.v_3>
A31: t | B31: delta_t | C31: 0 | D31: 0.03 | E31: 0.05999999 | F31: 0.08999999 | G31: 0.3 | H31: 0.6 | I31: 0.9 | J31: 2 | K31: 4 | L31: 6
A32: r | B32: 0 | C32: 0 | D32: 0.00068310003 | E32: 0.00096532808 | F32: 0.0012036767 | G32: 0.0036558212 | H32: 0.008812366 | I32: 0.014467188 | J32: 0.018879026 | K32: 0.018633558 | L32: 0.019919242
A33: r | B33: 0.1 | C33: -0.00033380969 | D33: 0.000384465 | E33: 0.0007591154 | F33: 0.0016071395 | G33: 0.004127086 | H33: 0.0085294568 | I33: 0.014020018 | J33: 0.019983013 | K33: 0.019622007 | L33: 0.020728161
A34: r | B34: 0.2 | C34: 1.2015331e-05 | D34: 0.00081896044 | E34: 0.00098415941 | F34: 0.001079239 | G34: 0.0033425209 | H34: 0.0089919429 | I34: 0.015240386 | J34: 0.019023971 | K34: 0.019882769 | L34: 0.02109273
A35: r | B35: 0.3 | C35: 0.00083400361 | D35: 0.0015388011 | E35: 0.0015492538 | F35: 0.0015643156 | G35: 0.0041194384 | H35: 0.008129889 | I35: 0.014798012 | J35: 0.019225469 | K35: 0.019136105 | L35: 0.020583961
A36: r | B36: 0.4 | C36: 0.00095376213 | D36: 0.0013364333 | E36: 0.0015023031 | F36: 0.0018522524 | G36: 0.0039548726 | H36: 0.0099352974 | I36: 0.014472162 | J36: 0.020077949 | K36: 0.018360008 | L36: 0.020956421
A37: r | B37: 0.8 | C37: 0.0025926047 | D37: 0.0028303222 | E37: 0.0033722768 | F37: 0.0036527674 | G37: 0.0061860001 | H37: 0.0098580203 | I37: 0.013623283 | J37: 0.020115529 | K37: 0.017409251 | L37: 0.020778111
A38: r | B38: 1.2 | C38: 0.0048686464 | D38: 0.004932827 | E38: 0.0051442104 | F38: 0.0054710048 | G38: 0.0076635656 | H38: 0.01045104 | I38: 0.013837476 | J38: 0.016144131 | K38: 0.01608231 | L38: 0.019185578
A39: r | B39: 1.6 | C39: 0.0061830015 | D39: 0.006337096 | E39: 0.0067682692 | F39: 0.0069364764 | G39: 0.0088430016 | H39: 0.010763798 | I39: 0.011633235 | J39: 0.012223411 | K39: 0.014564784 | L39: 0.01520681
A42: <Delta.v_2*Delta.v_1>
A43: t | B43: delta_t | C43: 0 | D43: 0.03 | E43: 0.05999999 | F43: 0.08999999 | G43: 0.3 | H43: 0.6 | I43: 0.9 | J43: 2 | K43: 4 | L43: 6
A44: r | B44: 0 | C44: 0 | D44: -9.5987009e-05 | E44: -0.00030934865 | F44: -0.00054183402 | G44: -9.9075645e-05 | H44: 5.8691487e-06 | I44: 0.00092497391 | J44: 0.0013686374 | K44: 0.0017400903 | L44: 0.0017954562
A45: r | B45: 0.1 | C45: -0.00089539481 | D45: -0.00053621299 | E45: -0.00051116262 | F45: -0.00088862067 | G45: 0.000942114 | H45: 5.7993746e-05 | I45: 0.00052432357 | J45: 0.0025163061 | K45: 0.0014254782 | L45: 0.00014809679
A46: r | B46: 0.2 | C46: 4.9753021e-05 | D46: -0.00036846962 | E46: -0.00037184444 | F46: -0.00072974394 | G46: 0.00036716874 | H46: 0.00030529778 | I46: 0.00042848134 | J46: 0.0022077266 | K46: 0.00075919947 | L46: -0.0011963886
A47: r | B47: 0.3 | C47: 0.00018454875 | D47: 0.0003080822 | E47: 0.00021862336 | F47: -0.00083866206 | G47: 0.0005128628 | H47: 0.00072512582 | I47: 0.00057606885 | J47: 0.00064598165 | K47: 0.0009934032 | L47: -0.0023816795
A48: r | B48: 0.4 | C48: -0.0006656009 | D48: -0.00056227401 | E48: -0.00031449837 | F48: -0.00020634764 | G48: 0.00043165599 | H48: 0.00049062656 | I48: -4.224871e-05 | J48: -0.00029561698 | K48: -0.00093115946 | L48: -0.0041423755
A49: r | B49: 0.8 | C49: -0.00073820918 | D49: -0.00074819072 | E49: -0.00027978562 | F49: -0.00053411095 | G49: -0.0018637481 | H49: -0.0013239512 | I49: -0.0015690024 | J49: -0.00071801377 | K49: -0.0029788824 | L49: -0.006780042
A50: r | B50: 1.2 | C50: 8.611816e-05 | D50: -0.00010695324 | E50: -0.00079831973 | F50: -0.00075005882 | G50: -0.0015679273 | H50: -0.002095015 | I50: -0.0024766906 | J50: -0.0020804441 | K50: -0.0069614594 | L50: -0.0097273848
...

Sheet 1_2
A1: Nmb_of_pts | B1: 150000, time_0 | C1: 0.2
A6: <Delta.v_1*Delta.v_1>
A7: t | B7: delta_t | C7: 0 | D7: 0.0001000017 | E7: 0.0002000034 | F7: 0.0003000051 | G7: 0.4 | H7: 0.8 | I7: 1.2 | J7: 1.75 | K7: 3.5 | L7: 5.25
A8: r | B8: 0 | C8: 0 | D8: 0 | E8: 0 | F8: 0 | G8: -0.10215515 | H8: -0.14575466 | I8: -0.18410043 | J8: -0.22799291 | K8: -0.28275592 | L8: -0.31360165
A9: r | B9: 0.1 | C9: -0.040894216 | D9: -0.040894216 | E9: -0.040894216 | F9: -0.040894216 | G9: -0.1040266 | H9: -0.14860499 | I9: -0.18497683 | J9: -0.22869488 | K9: -0.28300435 | L9: -0.31339077
A10: r | B10: 0.2 | C10: -0.070231175 | D10: -0.070231175 | E10: -0.070231175 | F10: -0.070231175 | G10: -0.11169164 | H10: -0.1514828 | I10: -0.18776946 | J10: -0.23018362 | K10: -0.28406938 | L10: -0.31443048
A11: r | B11: 0.3 | C11: -0.09447351 | D11: -0.09447351 | E11: -0.09447351 | F11: -0.09447351 | G11: -0.12146103 | H11: -0.15832788 | I11: -0.19165603 | J11: -0.23235022 | K11: -0.28488572 | L11: -0.3155718
A12: r | B12: 0.4 | C12: -0.11604187 | D12: -0.11604187 | E12: -0.11604187 | F12: -0.11604187 | G12: -0.13423897 | H12: -0.16569128 | I12: -0.19685664 | J12: -0.2358694 | K12: -0.2872799 | L12: -0.31796226
A13: r | B13: 0.8 | C13: -0.18691773 | D13: -0.18691773 | E13: -0.18691773 | F13: -0.18691773 | G13: -0.19381286 | H13: -0.20934429 | I13: -0.22695525 | J13: -0.25666374 | K13: -0.29968338 | L13: -0.32692912
A14: r | B14: 1.2 | C14: -0.24296243 | D14: -0.24296243 | E14: -0.24296243 | F14: -0.24296243 | G14: -0.24752728 | H14: -0.25379251 | I14: -0.26599545 | J14: -0.28277985 | K14: -0.3161209 | L14: -0.34151075
A15: r | B15: 1.6 | C15: -0.2899855 | D15: -0.2899855 | E15: -0.2899855 | F15: -0.2899855 | G15: -0.29277504 | H15: -0.29780011 | I15: -0.30218343 | J15: -0.31208491 | K15: -0.33537296 | L15: -0.35519841
A18: <Delta.v_1*Delta.v_2>
A19: t | B19: delta_t | C19: 0 | D19: 0.0001000017 | E19: 0.0002000034 | F19: 0.0003000051 | G19: 0.4 | H19: 0.8 | I19: 1.2 | J19: 1.75 | K19: 3.5 | L19: 5.25
A20: r | B20: 0 | C20: 0 | D20: 0 | E20: 0 | F20: 0 | G20: 0.0019724482 | H20: -0.00036394119 | I20: -0.00023983361 | J20: -0.00098214885 | K20: 0.0030115602 | L20: 0.0017186343
A21: r | B21: 0.1 | C21: 0.00058014537 | D21: 0.00058014537 | E21: 0.00058014537 | F21: 0.00058014537 | G21: 0.0017607936 | H21: 0.0012653278 | I21: -5.3420357e-05 | J21: -0.00047451067 | K21: 0.0027258487 | L21: 0.0017504924
A22: r | B22: 0.2 | C22: 0.00059448225 | D22: 0.00059448225 | E22: 0.00059448225 | F22: 0.00059448225 | G22: 0.0011399059 | H22: 0.0016912339 | I22: 0.00025376688 | J22: 0.00056627174 | K22: 0.0026431641 | L22: 0.0014002069
A23: r | B23: 0.3 | C23: 0.00021282532 | D23: 0.00021282532 | E23: 0.00021282532 | F23: 0.00021282532 | G23: 0.0013225039 | H23: 0.0012344005 | I23: -0.00055618107 | J23: 0.00081086681 | K23: 0.00051054229 | L23: 0.00056182787
A24: r | B24: 0.4 | C24: 0.00031626759 | D24: 0.00031626759 | E24: 0.00031626759 | F24: 0.00031626759 | G24: 0.0010377415 | H24: 0.0014264877 | I24: -0.00027632445 | J24: 0.0017742661 | K24: -0.00051429505 | L24: 2.3691861e-05
A25: r | B25: 0.8 | C25: 0.00042091464 | D25: 0.00042091464 | E25: 0.00042091464 | F25: 0.00042091464 | G25: -0.000304485 | H25: 0.00010528435 | I25: -0.00016088021 | J25: -0.00053355026 | K25: -0.001803144 | L25: -0.0031176579
A26: r | B26: 1.2 | C26: 0.00067530598 | D26: 0.00067530598 | E26: 0.00067530598 | F26: 0.00067530598 | G26: 0.0003130503 | H26: -0.00030952262 | I26: -0.0010163296 | J26: -0.0010260287 | K26: -0.0041436607 | L26: -0.0070040403
A27: r | B27: 1.6 | C27: 0.00011909652 | D27: 0.00011909652 | E27: 0.00011909652 | F27: 0.00011909652 | G27: 0.00096493921 | H27: 0.00046124668 | I27: 0.00063609185 | J27: -0.0010758423 | K27: -0.0054413879 | L27: -0.010873227
A30: <Delta.v_1*Delta.v_3>
A31: t | B31: delta_t | C31: 0 | D31: 0.0001000017 | E31: 0.0002000034 | F31: 0.0003000051 | G31: 0.4 | H31: 0.8 | I31: 1.2 | J31: 1.75 | K31: 3.5 | L31: 5.25
A32: r | B32: 0 | C32: 0 | D32: 0 | E32: 0 | F32: 0 | G32: 0.0073302487 | H32: 0.013821936 | I32: 0.018229172 | J32: 0.020176727 | K32: 0.014870486 | L32: 0.019731826
A33: r | B33: 0.1 | C33: 0.0012293126 | D33: 0.0012293126 | E33: 0.0012293126 | F33: 0.0012293126 | G33: 0.0069266225 | H33: 0.013281374 | I33: 0.017960396 | J33: 0.020588362 | K33: 0.014507938 | L33: 0.019873358
A34: r | B34: 0.2 | C34: 0.001357582 | D34: 0.001357582 | E34: 0.001357582 | F34: 0.001357582 | G34: 0.007055727 | H34: 0.012971767 | I34: 0.017708505 | J34: 0.020006267 | K34: 0.014989034 | L34: 0.019733578
A35: r | B35: 0.3 | C35: 0.0024160979 | D35: 0.0024160979 | E35: 0.0024160979 | F35: 0.0024160979 | G35: 0.006972165 | H35: 0.013444083 | I35: 0.018656023 | J35: 0.019766729 | K35: 0.015500051 | L35: 0.020075566
A36: r | B36: 0.4 | C36: 0.0024502853 | D36: 0.0024502853 | E36: 0.0024502853 | F36: 0.0024502853 | G36: 0.0067648566 | H36: 0.012722697 | I36: 0.017971302 | J36: 0.020287198 | K36: 0.016005177 | L36: 0.021201606
A37: r | B37: 0.8 | C37: 0.0032728668 | D37: 0.0032728668 | E37: 0.0032728668 | F37: 0.0032728668 | G37: 0.0086441174 | H37: 0.012726936 | I37: 0.015907776 | J37: 0.018378963 | K37: 0.015249157 | L37: 0.021748417
A38: r | B38: 1.2 | C38: 0.004601978 | D38: 0.004601978 | E38: 0.004601978 | F38: 0.004601978 | G38: 0.0079738164 | H38: 0.012424421 | I38: 0.014476899 | J38: 0.016534242 | K38: 0.014403353 | L38: 0.019705494
A39: r | B39: 1.6 | C39: 0.005032041 | D39: 0.005032041 | E39: 0.005032041 | F39: 0.005032041 | G39: 0.007994895 | H39: 0.010014412 | I39: 0.012683504 | J39: 0.013313566 | K39: 0.014095637 | L39: 0.017068777
A42: <Delta.v_2*Delta.v_1>
A43: t | B43: delta_t | C43: 0 | D43: 0.0001000017 | E43: 0.0002000034 | F43: 0.0003000051 | G43: 0.4 | H43: 0.8 | I43: 1.2 | J43: 1.75 | K43: 3.5 | L43: 5.25
A44: r | B44: 0 | C44: 0 | D44: 0 | E44: 0 | F44: 0 | G44: -0.00061261232 | H44: -0.0018343631 | I44: -0.0010698521 | J44: -0.0010305425 | K44: -0.00073182747 | L44: -0.00014587879
A45: r | B45: 0.1 | C45: 0.00011528408 | D45: 0.00011528408 | E45: 0.00011528408 | F45: 0.00011528408 | G45: -0.0010681705 | H45: -0.001828399 | I45: -0.0018989649 | J45: -0.001025714 | K45: -0.00082426409 | L45: -0.0012096106
A46: r | B46: 0.2 | C46: 4.9689001e-05 | D46: 4.9689001e-05 | E46: 4.9689001e-05 | F46: 4.9689001e-05 | G46: -0.00065598251 | H46: -0.0028178979 | I46: -0.0025653572 | J46: -0.00070481538 | K46: -0.00070133529 | L46: -0.0018272312
A47: r | B47: 0.3 | C47: 0.00032232432 | D47: 0.00032232432 | E47: 0.00032232432 | F47: 0.00032232432 | G47: -0.000882549 | H47: -0.0029399012 | I47: -0.002312163 | J47: -0.0013078627 | K47: -0.0014121269 | L47: -0.0024172951
A48: r | B48: 0.4 | C48: 0.00040181815 | D48: 0.00040181815 | E48: 0.00040181815 | F48: 0.00040181815 | G48: -0.00024826659 | H48: -0.0024442648 | I48: -0.0019050932 | J48: -0.00094180976 | K48: -0.0021447804 | L48: -0.0033215927
A49: r | B49: 0.8 | C49: 0.0013113968 | D49: 0.0013113968 | E49: 0.0013113968 | F49: 0.0013113968 | G49: -0.00031958519 | H49: -0.0018489322 | I49: -0.0029785265 | J49: -0.0022439442 | K49: -0.0034244981 | L49: -0.0056690836
A50: r | B50: 1.2 | C50: 0.00069835079 | D50: 0.00069835079 | E50: 0.00069835079 | F50: 0.00069835079 | G50: 0.00026475583 | H50: -0.00079069336 | I50: -0.00039250178 | J50: -0.0019725034 | K50: -0.0057869141 | L50: -0.0083692865
...

Sheet Итог
A2: delta_t(v_L)delta_t(v_L)_norm | C2: =_1_0!N122 -> 0 | D2: =_1_0!O122 -> 0.05 | E2: =_1_0!P122 -> 0.1 | F2: =_1_0!Q122 -> 0.15 | G2: =_1_0!R122 -> 0.5 | H2: =_1_0!S122 -> 1 | I2: =_1_0!T122 -> 1.5 | J2: =_1_0!U122 -> 2.5 | ... L2: =_1_0!W122 -> 7.5 | M2: =_1_1!O122 -> 0.03 | N2: =_1_1!P122 -> 0.05999999 | O2: =_1_1!Q122 -> 0.08999999 | P2: =_1_1!R122 -> 0.3 | Q2: =_1_1!S122 -> 0.6 | R2: =_1_1!T122 -> 0.9 | S2: =_1_1!U122 -> 2 | T2: =_1_1!V122 -> 4 | U2: =_1_1!W122 -> 6 | V2: ='1_2'!N122 -> 0.4 | W2: ='1_2'!O122 -> 0.8 | X2: ='1_2'!P122 -> 1.2 | Y2: ='1_2'!Q122 -> 1.75 | Z2: ='1_2'!R122 -> 3.5 | AA2: ='1_2'!S122 -> 5.25
B3: =_1_0!B123 -> 0.1 | C3: =_1_0!N123 -> 1 | D3: =_1_0!O123 -> 0.46402379 | E3: =_1_0!P123 -> 0.22443926 | F3: =_1_0!Q123 -> 0.13958908 | G3: =_1_0!R123 -> 0.054033398 | H3: =_1_0!S123 -> 0.030889986 | I3: =_1_0!T123 -> 0.020075335 | J3: =_1_0!U123 -> -0.00024516436 | ... L3: =_1_0!W123 -> -0.00058348782 | M3: =_1_1!O123 -> 0.6728238 | N3: =_1_1!P123 -> 0.40185353 | O3: =_1_1!Q123 -> 0.26749458 | P3: =_1_1!R123 -> 0.071272589 | Q3: =_1_1!S123 -> 0.059853168 | R3: =_1_1!T123 -> 0.02740771 | S3: =_1_1!U123 -> 0.0068716339 | T3: =_1_1!V123 -> 0.0048748621 | U3: =_1_1!W123 -> 0.00089127183 | V3: ='1_2'!N123 -> 0.045763272 | W3: ='1_2'!O123 -> 0.069700167 | X3: ='1_2'!P123 -> 0.021430946 | Y3: ='1_2'!Q123 -> 0.017165587 | Z3: ='1_2'!R123 -> 0.0060749373 | AA3: ='1_2'!S123 -> -0.0051568091
B4: =_1_0!B124 -> 0.2 | C4: =_1_0!N124 -> 1 | D4: =_1_0!O124 -> 0.64992521 | E4: =_1_0!P124 -> 0.41435578 | F4: =_1_0!Q124 -> 0.29559345 | G4: =_1_0!R124 -> 0.10627867 | H4: =_1_0!S124 -> 0.068002021 | I4: =_1_0!T124 -> 0.032329262 | J4: =_1_0!U124 -> 0.008737178 | ... L4: =_1_0!W124 -> 0.0032232547 | M4: =_1_1!O124 -> 0.79434197 | N4: =_1_1!P124 -> 0.58934008 | O4: =_1_1!Q124 -> 0.45459158 | P4: =_1_1!R124 -> 0.15692686 | Q4: =_1_1!S124 -> 0.099034915 | R4: =_1_1!T124 -> 0.067380021 | S4: =_1_1!U124 -> 0.032037358 | T4: =_1_1!V124 -> 0.022338974 | U4: =_1_1!W124 -> 0.01357708 | V4: ='1_2'!N124 -> 0.13578717 | W4: ='1_2'!O124 -> 0.081561257 | X4: ='1_2'!P124 -> 0.05224229 | Y4: ='1_2'!Q124 -> 0.031192812 | Z4: ='1_2'!R124 -> 0.018701982 | AA4: ='1_2'!S124 -> 0.011801461
B5: =_1_0!B125 -> 0.3 | C5: =_1_0!N125 -> 1 | D5: =_1_0!O125 -> 0.72769234 | E5: =_1_0!P125 -> 0.53701469 | F5: =_1_0!Q125 -> 0.41764198 | G5: =_1_0!R125 -> 0.17341297 | H5: =_1_0!S125 -> 0.099265311 | I5: =_1_0!T125 -> 0.048826813 | J5: =_1_0!U125 -> 0.018602438 | ... L5: =_1_0!W125 -> 0.0033793366 | M5: =_1_1!O125 -> 0.84256922 | N5: =_1_1!P125 -> 0.68290845 | O5: =_1_1!Q125 -> 0.57164773 | P5: =_1_1!R125 -> 0.24876221 | Q5: =_1_1!S125 -> 0.15090238 | R5: =_1_1!T125 -> 0.10904683 | S5: =_1_1!U125 -> 0.044264821 | T5: =_1_1!V125 -> 0.026410802 | U5: =_1_1!W125 -> 0.016903082 | V5: ='1_2'!N125 -> 0.20435234 | W5: ='1_2'!O125 -> 0.13308728 | X5: ='1_2'!P125 -> 0.079975862 | Y5: ='1_2'!Q125 -> 0.046122035 | Z5: ='1_2'!R125 -> 0.022543854 | AA5: ='1_2'!S125 -> 0.020853951
B6: =_1_0!B126 -> 0.4 | C6: =_1_0!N126 -> 1 | D6: =_1_0!O126 -> 0.77656752 | E6: =_1_0!P126 -> 0.60850239 | F6: =_1_0!Q126 -> 0.50324927 | G6: =_1_0!R126 -> 0.23165717 | H6: =_1_0!S126 -> 0.13424135 | I6: =_1_0!T126 -> 0.0761418 | J6: =_1_0!U126 -> 0.033846202 | ... L6: =_1_0!W126 -> 0.0077240563 | M6: =_1_1!O126 -> 0.8718769 | N6: =_1_1!P126 -> 0.73850002 | O6: =_1_1!Q126 -> 0.64264326 | P6: =_1_1!R126 -> 0.32717521 | Q6: =_1_1!S126 -> 0.20872182 | R6: =_1_1!T126 -> 0.15034186 | S6: =_1_1!U126 -> 0.064399192 | T6: =_1_1!V126 -> 0.037179229 | U6: =_1_1!W126 -> 0.022996285 | V6: ='1_2'!N126 -> 0.27648488 | W6: ='1_2'!O126 -> 0.17180545 | X6: ='1_2'!P126 -> 0.1099277 | Y6: ='1_2'!Q126 -> 0.067876236 | Z6: ='1_2'!R126 -> 0.038985794 | AA6: ='1_2'!S126 -> 0.037577889
B7: =_1_0!B127 -> 0.8 | C7: =_1_0!N127 -> 1 | D7: =_1_0!O127 -> 0.85999729 | E7: =_1_0!P127 -> 0.75557119 | F7: =_1_0!Q127 -> 0.68298181 | G7: =_1_0!R127 -> 0.42636614 | H7: =_1_0!S127 -> 0.27488108 | I7: =_1_0!T127 -> 0.1773438 | J7: =_1_0!U127 -> 0.071906346 | ... L7: =_1_0!W127 -> 0.032194131 | M7: =_1_1!O127 -> 0.91791752 | N7: =_1_1!P127 -> 0.83420982 | O7: =_1_1!Q127 -> 0.7726359 | P7: =_1_1!R127 -> 0.5394074 | Q7: =_1_1!S127 -> 0.38885582 | R7: =_1_1!T127 -> 0.29795489 | S7: =_1_1!U127 -> 0.13589981 | T7: =_1_1!V127 -> 0.080558413 | U7: =_1_1!W127 -> 0.059394463 | V7: ='1_2'!N127 -> 0.49036391 | W7: ='1_2'!O127 -> 0.34020116 | X7: ='1_2'!P127 -> 0.22927107 | Y7: ='1_2'!Q127 -> 0.15338745 | Z7: ='1_2'!R127 -> 0.090561023 | AA7: ='1_2'!S127 -> 0.071301243
B8: =_1_0!B128 -> 1.2 | C8: =_1_0!N128 -> 1 | D8: =_1_0!O128 -> 0.8943672 | E8: =_1_0!P128 -> 0.8140183 | F8: =_1_0!Q128 -> 0.75914961 | G8: =_1_0!R128 -> 0.5478866 | H8: =_1_0!S128 -> 0.38405783 | I8: =_1_0!T128 -> 0.26774908 | J8: =_1_0!U128 -> 0.12640462 | ... L8: =_1_0!W128 -> 0.056789204 | M8: =_1_1!O128 -> 0.93879927 | N8: =_1_1!P128 -> 0.87430559 | O8: =_1_1!Q128 -> 0.82642328 | P8: =_1_1!R128 -> 0.64402122 | Q8: =_1_1!S128 -> 0.50422435 | R8: =_1_1!T128 -> 0.40632052 | S8: =_1_1!U128 -> 0.19358304 | T8: =_1_1!V128 -> 0.12877903 | U8: =_1_1!W128 -> 0.091499454 | V8: ='1_2'!N128 -> 0.59833172 | W8: ='1_2'!O128 -> 0.44466896 | X8: ='1_2'!P128 -> 0.3370687 | Y8: ='1_2'!Q128 -> 0.22549552 | Z8: ='1_2'!R128 -> 0.1373257 | AA8: ='1_2'!S128 -> 0.11487
B9: =_1_0!B129 -> 1.6 | C9: =_1_0!N129 -> 1 | D9: =_1_0!O129 -> 0.90978327 | E9: =_1_0!P129 -> 0.84101597 | F9: =_1_0!Q129 -> 0.79458803 | G9: =_1_0!R129 -> 0.61192747 | H9: =_1_0!S129 -> 0.46057471 | I9: =_1_0!T129 -> 0.33854542 | J9: =_1_0!U129 -> 0.17451545 | ... L9: =_1_0!W129 -> 0.075297121 | M9: =_1_1!O129 -> 0.94703206 | N9: =_1_1!P129 -> 0.89183966 | O9: =_1_1!Q129 -> 0.85295218 | P9: =_1_1!R129 -> 0.6946526 | Q9: =_1_1!S129 -> 0.57542468 | R9: =_1_1!T129 -> 0.48295029 | S9: =_1_1!U129 -> 0.24943434 | T9: =_1_1!V129 -> 0.1695048 | U9: =_1_1!W129 -> 0.12392258 | V9: ='1_2'!N129 -> 0.65734286 | W9: ='1_2'!O129 -> 0.5243209 | X9: ='1_2'!P129 -> 0.40720314 | Y9: ='1_2'!Q129 -> 0.28998692 | Z9: ='1_2'!R129 -> 0.18144716 | AA9: ='1_2'!S129 -> 0.14344427
A11: delta_t(v_L)delta_t(v_L)_norm_ord | C11: =C2 -> 0 | D11: =M2 -> 0.03 | E11: =D2 -> 0.05 | F11: =N2 -> 0.05999999 | G11: =O2 -> 0.08999999 | H11: =E2 -> 0.1 | I11: =F2 -> 0.15 | J11: =P2 -> 0.3 | K11: =V2 -> 0.4 | L11: =G2 -> 0.5 | M11: =Q2 -> 0.6 | N11: =W2 -> 0.8 | O11: =R2 -> 0.9 | P11: =H2 -> 1 | Q11: =X2 -> 1.2 | R11: =I2 -> 1.5 | S11: =Y2 -> 1.75 | T11: =S2 -> 2 | U11: =J2 -> 2.5 | V11: =Z2 -> 3.5 | W11: =T2 -> 4 | X11: =K2 -> 5 | Y11: =AA2 -> 5.25 | Z11: =U2 -> 6 | AA11: =L2 -> 7.5
B12: =B3 -> 0.1 | C12: =C3 -> 1 | D12: =M3 -> 0.6728238 | E12: =D3 -> 0.46402379 | F12: =N3 -> 0.40185353 | G12: =O3 -> 0.26749458 | H12: =E3 -> 0.22443926 | I12: =F3 -> 0.13958908 | J12: =P3 -> 0.071272589 | K12: =V3 -> 0.045763272 | L12: =G3 -> 0.054033398 | M12: =Q3 -> 0.059853168 | N12: =W3 -> 0.069700167 | O12: =R3 -> 0.02740771 | P12: =H3 -> 0.030889986 | Q12: =X3 -> 0.021430946 | R12: =I3 -> 0.020075335 | S12: =Y3 -> 0.017165587 | T12: =S3 -> 0.0068716339 | U12: =J3 -> -0.00024516436 | V12: =Z3 -> 0.0060749373 | W12: =T3 -> 0.0048748621 | X12: =K3 -> 0.0078558775 | Y12: =AA3 -> -0.0051568091 | Z12: =U3 -> 0.00089127183 | AA12: =L3 -> -0.00058348782
